<?xml version="1.0" encoding="UTF-8"?>
<!-- Generated by org.testng.reporters.JUnitReportReporter -->
<testsuite skipped="0" hostname="Yogi-PC" name="TestNG_Concepts.Hard_Assertion" tests="5" failures="3" timestamp="7 Nov 2020 10:38:41 GMT" time="0.067" errors="0">
  <testcase name="testcase4" time="0.005" classname="TestNG_Concepts.Hard_Assertion"/>
  <testcase name="testcase3" time="0.003" classname="TestNG_Concepts.Hard_Assertion">
    <failure type="java.lang.AssertionError" message="expected [true] but found [false]">
      <![CDATA[java.lang.AssertionError: expected [true] but found [false]
	at org.testng.Assert.fail(Assert.java:94)
	at org.testng.Assert.failNotEquals(Assert.java:513)
	at org.testng.Assert.assertTrue(Assert.java:42)
	at org.testng.Assert.assertTrue(Assert.java:52)
	at TestNG_Concepts.Hard_Assertion.testcase3(Hard_Assertion.java:31)
	at sun.reflect.NativeMethodAccessorImpl.invoke0(Native Method)
	at sun.reflect.NativeMethodAccessorImpl.invoke(Unknown Source)
	at sun.reflect.DelegatingMethodAccessorImpl.invoke(Unknown Source)
	at java.lang.reflect.Method.invoke(Unknown Source)
	at org.testng.internal.MethodInvocationHelper.invokeMethod(MethodInvocationHelper.java:100)
	at org.testng.internal.Invoker.invokeMethod(Invoker.java:646)
	at org.testng.internal.Invoker.invokeTestMethod(Invoker.java:811)
	at org.testng.internal.Invoker.invokeTestMethods(Invoker.java:1137)
	at org.testng.internal.TestMethodWorker.invokeTestMethods(TestMethodWorker.java:129)
	at org.testng.internal.TestMethodWorker.run(TestMethodWorker.java:112)
	at org.testng.TestRunner.privateRun(TestRunner.java:753)
	at org.testng.TestRunner.run(TestRunner.java:607)
	at org.testng.SuiteRunner.runTest(SuiteRunner.java:368)
	at org.testng.SuiteRunner.runSequentially(SuiteRunner.java:363)
	at org.testng.SuiteRunner.privateRun(SuiteRunner.java:321)
	at org.testng.SuiteRunner.run(SuiteRunner.java:270)
	at org.testng.SuiteRunnerWorker.runSuite(SuiteRunnerWorker.java:52)
	at org.testng.SuiteRunnerWorker.run(SuiteRunnerWorker.java:86)
	at org.testng.TestNG.runSuitesSequentially(TestNG.java:1284)
	at org.testng.TestNG.runSuitesLocally(TestNG.java:1209)
	at org.testng.TestNG.runSuites(TestNG.java:1124)
	at org.testng.TestNG.run(TestNG.java:1096)
	at org.testng.remote.AbstractRemoteTestNG.run(AbstractRemoteTestNG.java:132)
	at org.testng.remote.RemoteTestNG.initAndRun(RemoteTestNG.java:236)
	at org.testng.remote.RemoteTestNG.main(RemoteTestNG.java:81)
]]>
    </failure>
  </testcase> <!-- testcase3 -->
  <testcase name="testcase5" time="0.005" classname="TestNG_Concepts.Hard_Assertion">
    <failure type="java.lang.AssertionError" message="expected [true] but found [false]">
      <![CDATA[java.lang.AssertionError: expected [true] but found [false]
	at org.testng.Assert.fail(Assert.java:94)
	at org.testng.Assert.failNotEquals(Assert.java:513)
	at org.testng.Assert.assertTrue(Assert.java:42)
	at org.testng.Assert.assertTrue(Assert.java:52)
	at TestNG_Concepts.Hard_Assertion.testcase5(Hard_Assertion.java:49)
	at sun.reflect.NativeMethodAccessorImpl.invoke0(Native Method)
	at sun.reflect.NativeMethodAccessorImpl.invoke(Unknown Source)
	at sun.reflect.DelegatingMethodAccessorImpl.invoke(Unknown Source)
	at java.lang.reflect.Method.invoke(Unknown Source)
	at org.testng.internal.MethodInvocationHelper.invokeMethod(MethodInvocationHelper.java:100)
	at org.testng.internal.Invoker.invokeMethod(Invoker.java:646)
	at org.testng.internal.Invoker.invokeTestMethod(Invoker.java:811)
	at org.testng.internal.Invoker.invokeTestMethods(Invoker.java:1137)
	at org.testng.internal.TestMethodWorker.invokeTestMethods(TestMethodWorker.java:129)
	at org.testng.internal.TestMethodWorker.run(TestMethodWorker.java:112)
	at org.testng.TestRunner.privateRun(TestRunner.java:753)
	at org.testng.TestRunner.run(TestRunner.java:607)
	at org.testng.SuiteRunner.runTest(SuiteRunner.java:368)
	at org.testng.SuiteRunner.runSequentially(SuiteRunner.java:363)
	at org.testng.SuiteRunner.privateRun(SuiteRunner.java:321)
	at org.testng.SuiteRunner.run(SuiteRunner.java:270)
	at org.testng.SuiteRunnerWorker.runSuite(SuiteRunnerWorker.java:52)
	at org.testng.SuiteRunnerWorker.run(SuiteRunnerWorker.java:86)
	at org.testng.TestNG.runSuitesSequentially(TestNG.java:1284)
	at org.testng.TestNG.runSuitesLocally(TestNG.java:1209)
	at org.testng.TestNG.runSuites(TestNG.java:1124)
	at org.testng.TestNG.run(TestNG.java:1096)
	at org.testng.remote.AbstractRemoteTestNG.run(AbstractRemoteTestNG.java:132)
	at org.testng.remote.RemoteTestNG.initAndRun(RemoteTestNG.java:236)
	at org.testng.remote.RemoteTestNG.main(RemoteTestNG.java:81)
]]>
    </failure>
  </testcase> <!-- testcase5 -->
  <testcase name="testcase1" time="0.048" classname="TestNG_Concepts.Hard_Assertion">
    <failure type="java.lang.AssertionError" message="expected [true] but found [false]">
      <![CDATA[java.lang.AssertionError: expected [true] but found [false]
	at org.testng.Assert.fail(Assert.java:94)
	at org.testng.Assert.failNotEquals(Assert.java:513)
	at org.testng.Assert.assertTrue(Assert.java:42)
	at org.testng.Assert.assertTrue(Assert.java:52)
	at TestNG_Concepts.Hard_Assertion.testcase1(Hard_Assertion.java:13)
	at sun.reflect.NativeMethodAccessorImpl.invoke0(Native Method)
	at sun.reflect.NativeMethodAccessorImpl.invoke(Unknown Source)
	at sun.reflect.DelegatingMethodAccessorImpl.invoke(Unknown Source)
	at java.lang.reflect.Method.invoke(Unknown Source)
	at org.testng.internal.MethodInvocationHelper.invokeMethod(MethodInvocationHelper.java:100)
	at org.testng.internal.Invoker.invokeMethod(Invoker.java:646)
	at org.testng.internal.Invoker.invokeTestMethod(Invoker.java:811)
	at org.testng.internal.Invoker.invokeTestMethods(Invoker.java:1137)
	at org.testng.internal.TestMethodWorker.invokeTestMethods(TestMethodWorker.java:129)
	at org.testng.internal.TestMethodWorker.run(TestMethodWorker.java:112)
	at org.testng.TestRunner.privateRun(TestRunner.java:753)
	at org.testng.TestRunner.run(TestRunner.java:607)
	at org.testng.SuiteRunner.runTest(SuiteRunner.java:368)
	at org.testng.SuiteRunner.runSequentially(SuiteRunner.java:363)
	at org.testng.SuiteRunner.privateRun(SuiteRunner.java:321)
	at org.testng.SuiteRunner.run(SuiteRunner.java:270)
	at org.testng.SuiteRunnerWorker.runSuite(SuiteRunnerWorker.java:52)
	at org.testng.SuiteRunnerWorker.run(SuiteRunnerWorker.java:86)
	at org.testng.TestNG.runSuitesSequentially(TestNG.java:1284)
	at org.testng.TestNG.runSuitesLocally(TestNG.java:1209)
	at org.testng.TestNG.runSuites(TestNG.java:1124)
	at org.testng.TestNG.run(TestNG.java:1096)
	at org.testng.remote.AbstractRemoteTestNG.run(AbstractRemoteTestNG.java:132)
	at org.testng.remote.RemoteTestNG.initAndRun(RemoteTestNG.java:236)
	at org.testng.remote.RemoteTestNG.main(RemoteTestNG.java:81)
]]>
    </failure>
  </testcase> <!-- testcase1 -->
  <testcase name="testcase2" time="0.006" classname="TestNG_Concepts.Hard_Assertion"/>
</testsuite> <!-- TestNG_Concepts.Hard_Assertion -->
